{
  "comments": [
    {
      "key": {
        "uuid": "3c392f6c_2583dec2",
        "filename": "managesf/lib/auth/__init__.py",
        "patchSetId": 12
      },
      "lineNbr": 32,
      "author": {
        "id": 6
      },
      "writtenOn": "2020-04-17T09:59:42Z",
      "side": 1,
      "message": "I think this could easily hide a useful exception. Maybe we should not try/except here ?",
      "range": {
        "startLine": 32,
        "startChar": 0,
        "endLine": 32,
        "endChar": 35
      },
      "revId": "b2641d56e3b986c7518ea6d540b6b569924d6b79",
      "serverId": "6c1dc8ef-8b94-40e4-bd83-c2359d45ecc0",
      "unresolved": false
    },
    {
      "key": {
        "uuid": "98651812_2735ade8",
        "filename": "managesf/lib/auth/cauth.py",
        "patchSetId": 12
      },
      "lineNbr": 21,
      "author": {
        "id": 6
      },
      "writtenOn": "2020-04-17T09:59:42Z",
      "side": 1,
      "message": "Do we still need that compat ? we don\u0027t have python2 tests",
      "range": {
        "startLine": 19,
        "startChar": 0,
        "endLine": 21,
        "endChar": 33
      },
      "revId": "b2641d56e3b986c7518ea6d540b6b569924d6b79",
      "serverId": "6c1dc8ef-8b94-40e4-bd83-c2359d45ecc0",
      "unresolved": false
    }
  ]
}